Workbook

Sheet Контракты
A2: Номер контракт | B2: Дата контракта | C2: Название контракта | D2: Начальная максимальная цена контракта | E2: Стоимость заключения контракта | F2: Вид закупки | G2: Количество участников | H2: Подрядчик заключивший контракт | I2: Минимальная предложенная цена | J2: Контракты с СМП для крупных заказов
A3: 1/26 | B3: 46034 | C3: Поисковые работы и бурение скважины для добычи золота в месте 1 | D3: 5000000 | E3: 4500000 | F3: Электронный конкурс | G3: 3 | H3: ООО ЗОЛОТО | I3: 4450000 | J3: 0
A4: 2/26 | B4: 46035 | C4: Поисковые работы и бурение скважины для добычи золота в месте 2 | D4: 10000000 | E4: 9000000 | F4: Электронный конкурс | G4: 2 | H4: ООО ЗОЛОТО | I4: 9000000 | J4: 1
A5: 3/26 | B5: 46036 | C5: Поисковые работы и бурение скважины для добычи алмазов в месте 3 | D5: 12000000 | E5: 11200000 | F5: Электронный конкурс | G5: 2 | H5: ООО БРИЛИАНТЫ | I5: 11200000 | J5: 1
A6: 4/26 | B6: 46037 | C6: Поисковые работы и бурение скважины для добычи золота в месте 4 | D6: 4000000 | E6: 4000000 | F6: Электронный конкурс | G6: 6 | H6: ООО ДОБЫЧА | I6: 4000000 | J6: 0
A7: 5/26 | B7: 46038 | C7: Поисковые работы и бурение скважины для добычи золота в месте 5 | D7: 5000000 | E7: 5000000 | F7: Единственный поставщик | G7: 1 | H7: ГК ГЕОЛОГИЯ | I7: 5000000 | J7: 1
A8: 6/26 | B8: 46039 | C8: Поисковые работы и бурение скважины для добычи золота в месте 6 | D8: 20000000 | E8: 19500000 | F8: Электронный конкурс | G8: 2 | H8: ГК ГЕОЛОГИЯ | I8: 19500000 | J8: 1
A9: 7/26 | B9: 46040 | C9: Поисковые работы и бурение скважины для добычи золота в месте 7 | D9: 6800000 | E9: 6800000 | F9: Единственный поставщик | G9: 1 | H9: ГК ГЕОЛОГИЯ | I9: 6800000 | J9: 1
A10: 8/26 | B10: 46041 | C10: Поисковые работы и бурение скважины для добычи золота в месте 8 | D10: 9000000 | E10: 8600000 | F10: Электронный конкурс | G10: 3 | H10: ООО ЗОЛОТО | I10: 8600000 | J10: 1
A11: 9/26 | B11: 46042 | C11: Поисковые работы и бурение скважины для добычи золота в месте 9 | D11: 6500000 | E11: 6000000 | F11: Электронный конкурс | G11: 4 | H11: ООО БУРИМ | I11: 6000000 | J11: 0
A12: 10/26 | B12: 46043 | C12: Поисковые работы и бурение скважины для добычи алмазов в месте 10 | D12: 15000000 | E12: 15000000 | F12: Единственный поставщик | G12: 1 | H12: ГК ГЕОЛОГИЯ | I12: 15000000 | J12: 1

Sheet Этапы
A2: Номер контракт | B2: Номер этапа | C2: Плановая дата начала | D2: Плановая дата окончания | E2: Стоимость этапа
A3: 1/26 | B3: 1 | C3: 46034 | D3: 46112 | E3: 1125000
A4: 1/26 | B4: 2 | C4: 46113 | D4: 46203 | E4: 1125000
A5: 1/26 | B5: 3 | C5: 46204 | D5: 46295 | E5: 1000000
A6: 1/26 | B6: 4 | C6: 46296 | D6: 46371 | E6: 750000
A7: 2/26 | B7: 1 | C7: 46035 | D7: 46112 | E7: =Контракты!$E$4/4 -> 2250000
A8: 2/26 | B8: 2 | C8: 46113 | D8: 46203 | E8: =Контракты!$E$4/4 -> 2250000
A9: 2/26 | B9: 3 | C9: 46204 | D9: 46295 | E9: 2500000
A10: 2/26 | B10: 4 | C10: 46296 | D10: 46371 | E10: 2000000
A11: 3/26 | B11: 1 | C11: 46036 | D11: 46112 | E11: =Контракты!$E$5/4 -> 2800000
A12: 3/26 | B12: 2 | C12: 46113 | D12: 46203 | E12: =Контракты!$E$5/4 -> 2800000
A13: 3/26 | B13: 3 | C13: 46204 | D13: 46295 | E13: =Контракты!$E$5/4 -> 2800000
A14: 3/26 | B14: 4 | C14: 46296 | D14: 46371 | E14: =Контракты!$E$5/4 -> 2800000
A15: 4/26 | B15: 1 | C15: 46037 | D15: 46112 | E15: =Контракты!$E$6/4 -> 1000000
A16: 4/26 | B16: 2 | C16: 46113 | D16: 46203 | E16: =Контракты!$E$6/4 -> 1000000
A17: 4/26 | B17: 3 | C17: 46204 | D17: 46295 | E17: =Контракты!$E$6/4 -> 1000000
A18: 4/26 | B18: 4 | C18: 46296 | D18: 46371 | E18: =Контракты!$E$6/4 -> 1000000
A19: 5/26 | B19: 1 | C19: 46038 | D19: 46112 | E19: =Контракты!$E$7/4 -> 1250000
A20: 5/26 | B20: 2 | C20: 46113 | D20: 46203 | E20: =Контракты!$E$7/4 -> 1250000
A21: 5/26 | B21: 3 | C21: 46204 | D21: 46295 | E21: =Контракты!$E$7/4 -> 1250000
A22: 5/26 | B22: 4 | C22: 46296 | D22: 46371 | E22: =Контракты!$E$7/4 -> 1250000
A23: 6/26 | B23: 1 | C23: 46039 | D23: 46112 | E23: =Контракты!$E$8/4 -> 4875000
A24: 6/26 | B24: 2 | C24: 46113 | D24: 46203 | E24: =Контракты!$E$8/4 -> 4875000
A25: 6/26 | B25: 3 | C25: 46204 | D25: 46295 | E25: =Контракты!$E$8/4 -> 4875000
A26: 6/26 | B26: 4 | C26: 46296 | D26: 46371 | E26: =Контракты!$E$8/4 -> 4875000
A27: 7/26 | B27: 1 | C27: 46040 | D27: 46112 | E27: 1700000
A28: 7/26 | B28: 2 | C28: 46113 | D28: 46203 | E28: 1600000
A29: 7/26 | B29: 3 | C29: 46204 | D29: 46295 | E29: 1600000
A30: 7/26 | B30: 4 | C30: 46296 | D30: 46371 | E30: 1500000
A31: 8/26 | B31: 1 | C31: 46041 | D31: 46112 | E31: =Контракты!$E$10/4 -> 2150000
A32: 8/26 | B32: 2 | C32: 46113 | D32: 46203 | E32: =Контракты!$E$10/4 -> 2150000
A33: 8/26 | B33: 3 | C33: 46204 | D33: 46295 | E33: =Контракты!$E$10/4 -> 2150000
A34: 8/26 | B34: 4 | C34: 46296 | D34: 46371 | E34: =Контракты!$E$10/4 -> 2150000
A35: 9/26 | B35: 1 | C35: 46042 | D35: 46112 | E35: =Контракты!$E$11/4 -> 1500000
A36: 9/26 | B36: 2 | C36: 46113 | D36: 46203 | E36: =Контракты!$E$11/4 -> 1500000
A37: 9/26 | B37: 3 | C37: 46204 | D37: 46295 | E37: =Контракты!$E$11/4 -> 1500000
A38: 9/26 | B38: 4 | C38: 46296 | D38: 46371 | E38: =Контракты!$E$11/4 -> 1500000
A39: 10/26 | B39: 1 | C39: 46043 | D39: 46112 | E39: =Контракты!$E$12/4 -> 3750000
A40: 10/26 | B40: 2 | C40: 46113 | D40: 46203 | E40: =Контракты!$E$12/4 -> 3750000
A41: 10/26 | B41: 3 | C41: 46204 | D41: 46295 | E41: =Контракты!$E$12/4 -> 3750000
...

Sheet Доп соглашения
A2: Номер контракт | B2: Номер соглашения | C2: Дата соглашения | D2: Краткое содержание | E2: Изменение стоимости
A3: 1/26 | B3: 1 | C3: 46038 | D3: Уточнение реквизитов | E3: 0
A4: 5/26 | B4: 1 | C4: 46042 | D4: Уточнение реквизитов | E4: 0
A5: 1/26 | B5: 2 | C5: 46107 | D5: Уменьшение стоимости работ | E5: 4000000
A6: 7/26 | B6: 1 | C6: 46107 | D6: Уменьшение стоимости работ | E6: 6400000
A7: 2/26 | B7: 1 | C7: 46162 | D7: Перенос между этапами стоимости работ | E7: 0

Sheet Акты выполненных работ 
A2: Номер контракт | B2: Номер акта | C2: Номер этапа | D2: Дата акта | E2: Принят аванс из общей суммы | F2: Общая сумма акта | G2: Сумма по субподрядчику | H2: Наименование субподрядчика
A3: 1/26 | B3: 1 | C3: 1 | D3: 46093 | E3: 337500 | F3: 1125000 | G3: 112500 | H3: ООО ДОБЫВАЕМ
A4: 2/26 | B4: 1 | C4: 1 | D4: 46093 | E4: 675000 | F4: 2250000 | G4: 337500 | H4: ООО ПОМОГАЕМ
A5: 3/26 | B5: 1 | C5: 1 | D5: 46093 | E5: 840000 | F5: 2800000 | G5: 280000 | H5: ООО КОПАЕМ
A6: 4/26 | B6: 1 | C6: 1 | D6: 46093 | E6: 300000 | F6: 1000000 | G6: 150000 | H6: ООО ПАРТНТЕР
A7: 5/26 | B7: 1 | C7: 1 | D7: 46093 | E7: 375000 | F7: 1250000 | G7: 187500 | H7: ООО ПРОЕКТИРУЕМ
A8: 6/26 | B8: 1 | C8: 1 | D8: 46093 | E8: 1462500 | F8: 4875000 | G8: 731250 | H8: ООО БУРИМ
A9: 7/26 | B9: 1 | C9: 1 | D9: 46093 | E9: 510000 | F9: 1700000 | G9: 255000 | H9: ООО ДОБЫВАЕМ
A10: 8/26 | B10: 1 | C10: 1 | D10: 46093 | E10: 645000 | F10: 2150000 | G10: 107500 | H10: ООО ПОМОГАЕМ
A11: 9/26 | B11: 1 | C11: 1 | D11: 46093 | E11: 450000 | F11: 1500000 | G11: 225000 | H11: ООО КОПАЕМ
A12: 10/26 | B12: 1 | C12: 1 | D12: 46093 | E12: 1125000 | F12: 3750000 | G12: 187500 | H12: ООО КОПАЕМ
A13: 1/26 | B13: 2 | C13: 2 | D13: 46197 | E13: 337500 | F13: 1125000 | G13: 112500 | H13: ООО ДОБЫВАЕМ
A14: 2/26 | B14: 2 | C14: 2 | D14: 46197 | E14: 675000 | F14: 2250000 | G14: 337500 | H14: ООО ПОМОГАЕМ
... A22: 10/26 | B22: 2 | C22: 2 | D22: 46197 | E22: 1125000 | F22: 3750000 | G22: 187500 | H22: ООО КОПАЕМ

Sheet Оплата работ 
A2: Номер контракта | B2: Тип оплаты | C2: Дата платежа | D2: номер платежного поручения | E2: Сумма оплаты | F2: Номер этапа
A3: 1/26 | B3: Аванс | C3: 46042 | D3: 11 | E3: 337500 | F3: 1
A4: 1/26 | B4: работы | C4: 46104 | D4: =D3+120 -> 131 | E4: 787500 | F4: 1
A5: 1/26 | B5: Аванс | C5: 46108 | D5: 160 | E5: 337500 | F5: 2
A6: 2/26 | B6: Аванс | C6: 46042 | D6: 12 | E6: 675000 | F6: 1
A7: 2/26 | B7: работы | C7: 46104 | D7: =D6+120 -> 132 | E7: 1575000 | F7: 1
A8: 2/26 | B8: Аванс | C8: 46107 | D8: =D7+17 -> 149 | E8: 675000 | F8: 2
A9: 3/26 | B9: Аванс | C9: 46042 | D9: 13 | E9: 840000 | F9: 1
A10: 3/26 | B10: работы | C10: 46104 | D10: =D9+120 -> 133 | E10: 1960000 | F10: 1
A11: 3/26 | B11: Аванс | C11: 46107 | D11: =D10+17 -> 150 | E11: 840000 | F11: 2
A12: 4/26 | B12: Аванс | C12: 46042 | D12: 14 | E12: 300000 | F12: 1
A13: 4/26 | B13: работы | C13: 46104 | D13: =D12+120 -> 134 | E13: 700000 | F13: 1
A14: 4/26 | B14: Аванс | C14: 46107 | D14: =D13+17 -> 151 | E14: 300000 | F14: 2
A15: 5/26 | B15: Аванс | C15: 46042 | D15: 15 | E15: 375000 | F15: 1
A16: 5/26 | B16: работы | C16: 46104 | D16: =D15+120 -> 135 | E16: 875000 | F16: 1
A17: 5/26 | B17: Аванс | C17: 46107 | D17: =D16+17 -> 152 | E17: 375000 | F17: 2
A18: 6/26 | B18: Аванс | C18: 46042 | D18: 17 | E18: 1462500 | F18: 1
A19: 6/26 | B19: работы | C19: 46104 | D19: =D18+120 -> 137 | E19: 3412500 | F19: 1
A20: 6/26 | B20: Аванс | C20: 46107 | D20: =D19+17 -> 154 | E20: 1462500 | F20: 2
A21: 7/26 | B21: Аванс | C21: 46042 | D21: 18 | E21: 510000 | F21: 1
A22: 7/26 | B22: работы | C22: 46104 | D22: =D21+120 -> 138 | E22: 1190000 | F22: 1
A23: 7/26 | B23: Аванс | C23: 46108 | D23: 162 | E23: 480000 | F23: 2
A24: 8/26 | B24: Аванс | C24: 46042 | D24: 19 | E24: 645000 | F24: 1
A25: 8/26 | B25: работы | C25: 46104 | D25: =D24+120 -> 139 | E25: 1505000 | F25: 1
A26: 8/26 | B26: Аванс | C26: 46107 | D26: =D25+17 -> 156 | E26: 645000 | F26: 2
A27: 9/26 | B27: Аванс | C27: 46042 | D27: 20 | E27: 450000 | F27: 1
A28: 9/26 | B28: работы | C28: 46104 | D28: =D27+120 -> 140 | E28: 1050000 | F28: 1
A29: 9/26 | B29: Аванс | C29: 46107 | D29: =D28+17 -> 157 | E29: 450000 | F29: 2
A30: 10/26 | B30: Аванс | C30: 46042 | D30: 22 | E30: 1125000 | F30: 1
A31: 10/26 | B31: работы | C31: 46104 | D31: =D30+120 -> 142 | E31: 2625000 | F31: 1
A32: 10/26 | B32: Аванс | C32: 46107 | D32: =D31+17 -> 159 | E32: 1125000 | F32: 2

Sheet Исполнение работ План
A1: номер контракта | B1: Дата | C1: бурение, м
A2: 1/26 | B2: 46142 | C2: 20
A3: 2/26 | B3: 46142 | C3: 25
A4: 3/26 | B4: 46142 | C4: 20
A5: 4/26 | B5: 46142 | C5: 25
A6: 5/26 | B6: 46142 | C6: 30
A7: 6/26 | B7: 46142 | C7: 27
A8: 7/26 | B8: 46142 | C8: 24
A9: 8/26 | B9: 46142 | C9: 27
A10: 9/26 | B10: 46142 | C10: 25
A11: 10/26 | B11: 46142 | C11: 25
A12: 1/26 | B12: 46173 | C12: 12
A13: 2/26 | B13: 46173 | C13: 13
... A91: 10/26 | B91: 46371 | C91: 13

Sheet Исполнение работ Факт
A1: номер контракта | B1: Дата | C1: Бурение, м
A2: 1/26 | B2: 46142 | C2: 19
A3: 2/26 | B3: 46142 | C3: 22.5
A4: 3/26 | B4: 46142 | C4: 20
A5: 4/26 | B5: 46142 | C5: 24
A6: 5/26 | B6: 46142 | C6: 29
A7: 6/26 | B7: 46142 | C7: 27
A8: 7/26 | B8: 46142 | C8: 24
A9: 8/26 | B9: 46142 | C9: 26
A10: 9/26 | B10: 46142 | C10: 24
A11: 10/26 | B11: 46142 | C11: 25
A12: 1/26 | B12: 46173 | C12: 13
A13: 2/26 | B13: 46173 | C13: 13.5
... A31: 10/26 | B31: 46203 | C31: 14
