Workbook

Sheet Контракты
A3: Номер контракт | B3: Дата контракта | C3: Название контракта | D3: Начальная максимальная цена контракта | E3: Стоимость заключения контракта | F3: Подрядчик заключивший контракт | G3: Минимальная предложенная цена | H3: Контракты с СМП для крупных заказов
A4: 1/26 | B4: 46034 | C4: Поисковые работы и бурение скважины для добычи золота в месте 1 | D4: 5000000 | E4: 4500000 | F4: ООО ЗОЛОТО | G4: 4450000 | H4: 0
A5: 2/26 | B5: 46035 | C5: Поисковые работы и бурение скважины для добычи золота в месте 2 | D5: 10000000 | E5: 9000000 | F5: ООО ЗОЛОТО | G5: 9000000 | H5: 1
A6: 3/26 | B6: 46036 | C6: Поисковые работы и бурение скважины для добычи алмазов в месте 3 | D6: 12000000 | E6: 11200000 | F6: ООО БРИЛИАНТЫ | G6: 11200000 | H6: 1
A7: 4/26 | B7: 46037 | C7: Поисковые работы и бурение скважины для добычи золота в месте 4 | D7: 4000000 | E7: 4000000 | F7: ООО ДОБЫЧА | G7: 4000000 | H7: 0
A8: 5/26 | B8: 46038 | C8: Поисковые работы и бурение скважины для добычи золота в месте 5 | D8: 5000000 | E8: 5000000 | F8: ГК ГЕОЛОГИЯ | G8: 5000000 | H8: 1
A9: 6/26 | B9: 46039 | C9: Поисковые работы и бурение скважины для добычи золота в месте 6 | D9: 20000000 | E9: 19500000 | F9: ГК ГЕОЛОГИЯ | G9: 19500000 | H9: 1
A10: 7/26 | B10: 46040 | C10: Поисковые работы и бурение скважины для добычи золота в месте 7 | D10: 6800000 | E10: 6800000 | F10: ГК ГЕОЛОГИЯ | G10: 6800000 | H10: 1
A11: 8/26 | B11: 46041 | C11: Поисковые работы и бурение скважины для добычи золота в месте 8 | D11: 9000000 | E11: 8600000 | F11: ООО ЗОЛОТО | G11: 8600000 | H11: 1
A12: 9/26 | B12: 46042 | C12: Поисковые работы и бурение скважины для добычи золота в месте 9 | D12: 6500000 | E12: 6000000 | F12: ООО БУРИМ | G12: 6000000 | H12: 0
A13: 10/26 | B13: 46043 | C13: Поисковые работы и бурение скважины для добычи алмазов в месте 10 | D13: 15000000 | E13: 15000000 | F13: ГК ГЕОЛОГИЯ | G13: 15000000 | H13: 1

Sheet Этапы
A2: Номер контракт | B2: Номер этапа | C2: Плановая дата начала | D2: Плановая дата окончания | E2: Стоимость этапа
A3: 1/26 | B3: 1 | C3: 46034 | D3: 46112 | E3: =Контракты!$E$4/4 -> 1125000
A4: 1/26 | B4: 2 | C4: 46113 | D4: 46203 | E4: =Контракты!$E$4/4 -> 1125000
A5: 1/26 | B5: 3 | C5: 46204 | D5: 46295 | E5: =Контракты!$E$4/4 -> 1125000
A6: 1/26 | B6: 4 | C6: 46296 | D6: 46371 | E6: =Контракты!$E$4/4 -> 1125000
A7: 2/26 | B7: 1 | C7: 46035 | D7: 46112 | E7: =Контракты!$E$5/4 -> 2250000
A8: 2/26 | B8: 2 | C8: 46113 | D8: 46203 | E8: =Контракты!$E$5/4 -> 2250000
A9: 2/26 | B9: 3 | C9: 46204 | D9: 46295 | E9: =Контракты!$E$5/4 -> 2250000
A10: 2/26 | B10: 4 | C10: 46296 | D10: 46371 | E10: =Контракты!$E$5/4 -> 2250000
A11: 3/26 | B11: 1 | C11: 46036 | D11: 46112 | E11: =Контракты!$E$6/4 -> 2800000
A12: 3/26 | B12: 2 | C12: 46113 | D12: 46203 | E12: =Контракты!$E$6/4 -> 2800000
A13: 3/26 | B13: 3 | C13: 46204 | D13: 46295 | E13: =Контракты!$E$6/4 -> 2800000
A14: 3/26 | B14: 4 | C14: 46296 | D14: 46371 | E14: =Контракты!$E$6/4 -> 2800000
A15: 4/26 | B15: 1 | C15: 46037 | D15: 46112 | E15: =Контракты!$E$7/4 -> 1000000
A16: 4/26 | B16: 2 | C16: 46113 | D16: 46203 | E16: =Контракты!$E$7/4 -> 1000000
A17: 4/26 | B17: 3 | C17: 46204 | D17: 46295 | E17: =Контракты!$E$7/4 -> 1000000
A18: 4/26 | B18: 4 | C18: 46296 | D18: 46371 | E18: =Контракты!$E$7/4 -> 1000000
A19: 5/26 | B19: 1 | C19: 46038 | D19: 46112 | E19: =Контракты!$E$8/4 -> 1250000
A20: 5/26 | B20: 2 | C20: 46113 | D20: 46203 | E20: =Контракты!$E$8/4 -> 1250000
A21: 5/26 | B21: 3 | C21: 46204 | D21: 46295 | E21: =Контракты!$E$8/4 -> 1250000
A22: 5/26 | B22: 4 | C22: 46296 | D22: 46371 | E22: =Контракты!$E$8/4 -> 1250000
A23: 6/26 | B23: 1 | C23: 46039 | D23: 46112 | E23: =Контракты!$E$9/4 -> 4875000
A24: 6/26 | B24: 2 | C24: 46113 | D24: 46203 | E24: =Контракты!$E$9/4 -> 4875000
A25: 6/26 | B25: 3 | C25: 46204 | D25: 46295 | E25: =Контракты!$E$9/4 -> 4875000
A26: 6/26 | B26: 4 | C26: 46296 | D26: 46371 | E26: =Контракты!$E$9/4 -> 4875000
A27: 7/26 | B27: 1 | C27: 46040 | D27: 46112 | E27: =Контракты!$E$10/4 -> 1700000
A28: 7/26 | B28: 2 | C28: 46113 | D28: 46203 | E28: =Контракты!$E$10/4 -> 1700000
A29: 7/26 | B29: 3 | C29: 46204 | D29: 46295 | E29: =Контракты!$E$10/4 -> 1700000
A30: 7/26 | B30: 4 | C30: 46296 | D30: 46371 | E30: =Контракты!$E$10/4 -> 1700000
A31: 8/26 | B31: 1 | C31: 46041 | D31: 46112 | E31: =Контракты!$E$11/4 -> 2150000
A32: 8/26 | B32: 2 | C32: 46113 | D32: 46203 | E32: =Контракты!$E$11/4 -> 2150000
A33: 8/26 | B33: 3 | C33: 46204 | D33: 46295 | E33: =Контракты!$E$11/4 -> 2150000
A34: 8/26 | B34: 4 | C34: 46296 | D34: 46371 | E34: =Контракты!$E$11/4 -> 2150000
A35: 9/26 | B35: 1 | C35: 46042 | D35: 46112 | E35: =Контракты!$E$12/4 -> 1500000
A36: 9/26 | B36: 2 | C36: 46113 | D36: 46203 | E36: =Контракты!$E$12/4 -> 1500000
A37: 9/26 | B37: 3 | C37: 46204 | D37: 46295 | E37: =Контракты!$E$12/4 -> 1500000
A38: 9/26 | B38: 4 | C38: 46296 | D38: 46371 | E38: =Контракты!$E$12/4 -> 1500000
A39: 10/26 | B39: 1 | C39: 46043 | D39: 46112 | E39: =Контракты!$E$13/4 -> 3750000
A40: 10/26 | B40: 2 | C40: 46113 | D40: 46203 | E40: =Контракты!$E$13/4 -> 3750000
A41: 10/26 | B41: 3 | C41: 46204 | D41: 46295 | E41: =Контракты!$E$13/4 -> 3750000
...

Sheet Доп соглашения
A2: Номер контракт | B2: Номер соглашения | C2: Дата соглашения | D2: Краткое содержание | E2: Изменение стоимости
A3: 1/26 | B3: 1 | C3: 46038 | D3: Уточнение реквизитов | E3: 0
A4: 5/26 | B4: 1 | C4: 46042 | D4: Уточнение реквизитов | E4: 0

Sheet Акты выполненных работ 
A2: Номер контракт | B2: Номер акта | C2: Номер этапа | D2: Дата акта | E2: Принят аванс из общей суммы | F2: Общая сумма акта | G2: Сумма по субподрядчику | H2: Наименование субподрядчика
A3: 1/26 | B3: 1 | C3: 1 | D3: 46093 | E3: 337500 | F3: 1125000 | G3: 112500 | H3: ООО ДОБЫВАЕМ
A4: 2/26 | B4: 1 | C4: 1 | D4: 46093 | E4: 675000 | F4: 2250000 | G4: 337500 | H4: ООО ПОМОГАЕМ
A5: 3/26 | B5: 1 | C5: 1 | D5: 46093 | E5: 840000 | F5: 2800000 | G5: 280000 | H5: ООО КОПАЕМ
A6: 4/26 | B6: 1 | C6: 1 | D6: 46093 | E6: 300000 | F6: 1000000 | G6: 150000 | H6: ООО ПАРТНТЕР
A7: 5/26 | B7: 1 | C7: 1 | D7: 46093 | E7: 375000 | F7: 1250000 | G7: 187500 | H7: ООО ПРОЕКТИРУЕМ
A8: 6/26 | B8: 1 | C8: 1 | D8: 46093 | E8: 1462500 | F8: 4875000 | G8: 731250 | H8: ООО БУРИМ
A9: 7/26 | B9: 1 | C9: 1 | D9: 46093 | E9: 510000 | F9: 1700000 | G9: 255000 | H9: ООО ДОБЫВАЕМ
A10: 8/26 | B10: 1 | C10: 1 | D10: 46093 | E10: 645000 | F10: 2150000 | G10: 107500 | H10: ООО ПОМОГАЕМ
A11: 9/26 | B11: 1 | C11: 1 | D11: 46093 | E11: 450000 | F11: 1500000 | G11: 225000 | H11: ООО КОПАЕМ
A12: 10/26 | B12: 1 | C12: 1 | D12: 46093 | E12: 1125000 | F12: 3750000 | G12: 187500 | H12: ООО КОПАЕМ

Sheet Оплата работ 
A2: Номер контракта | B2: Тип оплаты | C2: Дата платежа | D2: номер платежного поручения | E2: Сумма оплаты | F2: Номер этапа
A3: 1/26 | B3: Аванс | C3: 46042 | D3: 11 | E3: 337500 | F3: 1
A4: 2/26 | B4: Аванс | C4: 46042 | D4: 12 | E4: 675000 | F4: 1
A5: 3/26 | B5: Аванс | C5: 46042 | D5: 13 | E5: 840000 | F5: 1
A6: 4/26 | B6: Аванс | C6: 46042 | D6: 14 | E6: 300000 | F6: 1
A7: 5/26 | B7: Аванс | C7: 46042 | D7: 15 | E7: 375000 | F7: 1
A8: 6/26 | B8: Аванс | C8: 46042 | D8: 17 | E8: 1462500 | F8: 1
A9: 7/26 | B9: Аванс | C9: 46042 | D9: 18 | E9: 510000 | F9: 1
A10: 8/26 | B10: Аванс | C10: 46042 | D10: 19 | E10: 645000 | F10: 1
A11: 9/26 | B11: Аванс | C11: 46042 | D11: 20 | E11: 450000 | F11: 1
A12: 10/26 | B12: Аванс | C12: 46042 | D12: 22 | E12: 1125000 | F12: 1
